2025-06-12 19:31:22 [ERROR] [logger] Торговой пары BCTUSDT-26SEP25 не существует
2025-06-12 19:31:24 [ERROR] [logger] Торговой пары BCT-USDT-250926 не существует
2025-06-12 19:31:27 [ERROR] [logger] Торговой пары BCTUSDT_250926 не существует
2025-06-13 10:51:03 [ERROR] [logger] Торговой пары BТСUSDT-26SEP25 не существует
2025-06-13 10:51:06 [ERROR] [logger] Торговой пары BТС-USDT-250926 не существует
2025-06-13 10:51:11 [ERROR] [logger] Торговой пары BТСUSDT_250926 не существует
2025-06-13 12:35:56 [ERROR] [_application] No error handlers are registered, logging exception.
Traceback (most recent call last):
  File "C:\Proga\Python_project\Work\venv\Lib\site-packages\telegram\ext\_utils\networkloop.py", line 115, in network_retry_loop
    if not await do_action():
           ^^^^^^^^^^^^^^^^^
  File "C:\Proga\Python_project\Work\venv\Lib\site-packages\telegram\ext\_utils\networkloop.py", line 108, in do_action
    return action_cb_task.result()
           ^^^^^^^^^^^^^^^^^^^^^^^
  File "C:\Proga\Python_project\Work\venv\Lib\site-packages\telegram\ext\_updater.py", line 335, in polling_action_cb
    updates = await self.bot.get_updates(
              ^^^^^^^^^^^^^^^^^^^^^^^^^^^
  File "C:\Proga\Python_project\Work\venv\Lib\site-packages\telegram\ext\_extbot.py", line 669, in get_updates
    updates = await super().get_updates(
              ^^^^^^^^^^^^^^^^^^^^^^^^^^
  File "C:\Proga\Python_project\Work\venv\Lib\site-packages\telegram\_bot.py", line 4601, in get_updates
    await self._post(
  File "C:\Proga\Python_project\Work\venv\Lib\site-packages\telegram\_bot.py", line 697, in _post
    return await self._do_post(
           ^^^^^^^^^^^^^^^^^^^^
  File "C:\Proga\Python_project\Work\venv\Lib\site-packages\telegram\ext\_extbot.py", line 369, in _do_post
    return await super()._do_post(
           ^^^^^^^^^^^^^^^^^^^^^^^
  File "C:\Proga\Python_project\Work\venv\Lib\site-packages\telegram\_bot.py", line 726, in _do_post
    result = await request.post(
             ^^^^^^^^^^^^^^^^^^^
  File "C:\Proga\Python_project\Work\venv\Lib\site-packages\telegram\request\_baserequest.py", line 197, in post
    result = await self._request_wrapper(
             ^^^^^^^^^^^^^^^^^^^^^^^^^^^^
  File "C:\Proga\Python_project\Work\venv\Lib\site-packages\telegram\request\_baserequest.py", line 355, in _request_wrapper
    raise Conflict(message)
telegram.error.Conflict: Conflict: terminated by other getUpdates request; make sure that only one bot instance is running
2025-06-13 12:58:10 [ERROR] [logger] Торговой пары BTCUSDT-25DEC25 не существует
2025-06-13 12:58:10 [ERROR] [main] Analysis error: Ошибка валидации данных от Bybit. Проверьте вводимые данные. Для подробностей обратитесь к админу
2025-06-13 13:02:06 [ERROR] [logger] Торговой пары BTCUSDT_251226 не существует
2025-06-13 13:02:06 [ERROR] [main] Analysis error: Ошибка валидации данных от Bybit. Проверьте вводимые данные. Для подробностей обратитесь к админу
2025-06-13 13:02:51 [ERROR] [logger] Торговой пары BTCUSDT-25DEC26 не существует
2025-06-13 13:02:51 [ERROR] [main] Analysis error: Ошибка валидации данных от Bybit. Проверьте вводимые данные. Для подробностей обратитесь к админу
2025-06-13 13:03:24 [ERROR] [logger] Торговой пары BTCUSDT-25DEC25 не существует
2025-06-13 13:03:24 [ERROR] [main] Analysis error: Ошибка валидации данных от Bybit. Проверьте вводимые данные. Для подробностей обратитесь к админу
2025-06-13 13:03:33 [ERROR] [logger] Торговой пары BТСUSDT-26SEP25 не существует
2025-06-13 13:03:33 [ERROR] [main] Analysis error: Ошибка валидации данных от Bybit. Проверьте вводимые данные. Для подробностей обратитесь к админу
2025-06-13 13:07:26 [ERROR] [logger] Торговой пары BТСUSDT-26SEP25 не существует
2025-06-13 13:07:27 [ERROR] [main] Analysis error: Ошибка валидации данных от Bybit. Проверьте вводимые данные. Для подробностей обратитесь к админу
2025-06-13 13:09:40 [ERROR] [_application] No error handlers are registered, logging exception.
Traceback (most recent call last):
  File "C:\Proga\Python_project\Work\venv\Lib\site-packages\telegram\ext\_utils\networkloop.py", line 115, in network_retry_loop
    if not await do_action():
           ^^^^^^^^^^^^^^^^^
  File "C:\Proga\Python_project\Work\venv\Lib\site-packages\telegram\ext\_utils\networkloop.py", line 108, in do_action
    return action_cb_task.result()
           ^^^^^^^^^^^^^^^^^^^^^^^
  File "C:\Proga\Python_project\Work\venv\Lib\site-packages\telegram\ext\_updater.py", line 335, in polling_action_cb
    updates = await self.bot.get_updates(
              ^^^^^^^^^^^^^^^^^^^^^^^^^^^
  File "C:\Proga\Python_project\Work\venv\Lib\site-packages\telegram\ext\_extbot.py", line 669, in get_updates
    updates = await super().get_updates(
              ^^^^^^^^^^^^^^^^^^^^^^^^^^
  File "C:\Proga\Python_project\Work\venv\Lib\site-packages\telegram\_bot.py", line 4601, in get_updates
    await self._post(
  File "C:\Proga\Python_project\Work\venv\Lib\site-packages\telegram\_bot.py", line 697, in _post
    return await self._do_post(
           ^^^^^^^^^^^^^^^^^^^^
  File "C:\Proga\Python_project\Work\venv\Lib\site-packages\telegram\ext\_extbot.py", line 369, in _do_post
    return await super()._do_post(
           ^^^^^^^^^^^^^^^^^^^^^^^
  File "C:\Proga\Python_project\Work\venv\Lib\site-packages\telegram\_bot.py", line 726, in _do_post
    result = await request.post(
             ^^^^^^^^^^^^^^^^^^^
  File "C:\Proga\Python_project\Work\venv\Lib\site-packages\telegram\request\_baserequest.py", line 197, in post
    result = await self._request_wrapper(
             ^^^^^^^^^^^^^^^^^^^^^^^^^^^^
  File "C:\Proga\Python_project\Work\venv\Lib\site-packages\telegram\request\_baserequest.py", line 355, in _request_wrapper
    raise Conflict(message)
telegram.error.Conflict: Conflict: terminated by other getUpdates request; make sure that only one bot instance is running
2025-06-13 13:09:45 [ERROR] [_application] No error handlers are registered, logging exception.
Traceback (most recent call last):
  File "C:\Proga\Python_project\Work\venv\Lib\site-packages\telegram\ext\_utils\networkloop.py", line 115, in network_retry_loop
    if not await do_action():
           ^^^^^^^^^^^^^^^^^
  File "C:\Proga\Python_project\Work\venv\Lib\site-packages\telegram\ext\_utils\networkloop.py", line 108, in do_action
    return action_cb_task.result()
           ^^^^^^^^^^^^^^^^^^^^^^^
  File "C:\Proga\Python_project\Work\venv\Lib\site-packages\telegram\ext\_updater.py", line 335, in polling_action_cb
    updates = await self.bot.get_updates(
              ^^^^^^^^^^^^^^^^^^^^^^^^^^^
  File "C:\Proga\Python_project\Work\venv\Lib\site-packages\telegram\ext\_extbot.py", line 669, in get_updates
    updates = await super().get_updates(
              ^^^^^^^^^^^^^^^^^^^^^^^^^^
  File "C:\Proga\Python_project\Work\venv\Lib\site-packages\telegram\_bot.py", line 4601, in get_updates
    await self._post(
  File "C:\Proga\Python_project\Work\venv\Lib\site-packages\telegram\_bot.py", line 697, in _post
    return await self._do_post(
           ^^^^^^^^^^^^^^^^^^^^
  File "C:\Proga\Python_project\Work\venv\Lib\site-packages\telegram\ext\_extbot.py", line 369, in _do_post
    return await super()._do_post(
           ^^^^^^^^^^^^^^^^^^^^^^^
  File "C:\Proga\Python_project\Work\venv\Lib\site-packages\telegram\_bot.py", line 726, in _do_post
    result = await request.post(
             ^^^^^^^^^^^^^^^^^^^
  File "C:\Proga\Python_project\Work\venv\Lib\site-packages\telegram\request\_baserequest.py", line 197, in post
    result = await self._request_wrapper(
             ^^^^^^^^^^^^^^^^^^^^^^^^^^^^
  File "C:\Proga\Python_project\Work\venv\Lib\site-packages\telegram\request\_baserequest.py", line 355, in _request_wrapper
    raise Conflict(message)
telegram.error.Conflict: Conflict: terminated by other getUpdates request; make sure that only one bot instance is running
2025-06-13 13:09:51 [ERROR] [_application] No error handlers are registered, logging exception.
Traceback (most recent call last):
  File "C:\Proga\Python_project\Work\venv\Lib\site-packages\telegram\ext\_utils\networkloop.py", line 115, in network_retry_loop
    if not await do_action():
           ^^^^^^^^^^^^^^^^^
  File "C:\Proga\Python_project\Work\venv\Lib\site-packages\telegram\ext\_utils\networkloop.py", line 108, in do_action
    return action_cb_task.result()
           ^^^^^^^^^^^^^^^^^^^^^^^
  File "C:\Proga\Python_project\Work\venv\Lib\site-packages\telegram\ext\_updater.py", line 335, in polling_action_cb
    updates = await self.bot.get_updates(
              ^^^^^^^^^^^^^^^^^^^^^^^^^^^
  File "C:\Proga\Python_project\Work\venv\Lib\site-packages\telegram\ext\_extbot.py", line 669, in get_updates
    updates = await super().get_updates(
              ^^^^^^^^^^^^^^^^^^^^^^^^^^
  File "C:\Proga\Python_project\Work\venv\Lib\site-packages\telegram\_bot.py", line 4601, in get_updates
    await self._post(
  File "C:\Proga\Python_project\Work\venv\Lib\site-packages\telegram\_bot.py", line 697, in _post
    return await self._do_post(
           ^^^^^^^^^^^^^^^^^^^^
  File "C:\Proga\Python_project\Work\venv\Lib\site-packages\telegram\ext\_extbot.py", line 369, in _do_post
    return await super()._do_post(
           ^^^^^^^^^^^^^^^^^^^^^^^
  File "C:\Proga\Python_project\Work\venv\Lib\site-packages\telegram\_bot.py", line 726, in _do_post
    result = await request.post(
             ^^^^^^^^^^^^^^^^^^^
  File "C:\Proga\Python_project\Work\venv\Lib\site-packages\telegram\request\_baserequest.py", line 197, in post
    result = await self._request_wrapper(
             ^^^^^^^^^^^^^^^^^^^^^^^^^^^^
  File "C:\Proga\Python_project\Work\venv\Lib\site-packages\telegram\request\_baserequest.py", line 355, in _request_wrapper
    raise Conflict(message)
telegram.error.Conflict: Conflict: terminated by other getUpdates request; make sure that only one bot instance is running
2025-06-13 13:09:58 [ERROR] [_application] No error handlers are registered, logging exception.
Traceback (most recent call last):
  File "C:\Proga\Python_project\Work\venv\Lib\site-packages\telegram\ext\_utils\networkloop.py", line 115, in network_retry_loop
    if not await do_action():
           ^^^^^^^^^^^^^^^^^
  File "C:\Proga\Python_project\Work\venv\Lib\site-packages\telegram\ext\_utils\networkloop.py", line 108, in do_action
    return action_cb_task.result()
           ^^^^^^^^^^^^^^^^^^^^^^^
  File "C:\Proga\Python_project\Work\venv\Lib\site-packages\telegram\ext\_updater.py", line 335, in polling_action_cb
    updates = await self.bot.get_updates(
              ^^^^^^^^^^^^^^^^^^^^^^^^^^^
  File "C:\Proga\Python_project\Work\venv\Lib\site-packages\telegram\ext\_extbot.py", line 669, in get_updates
    updates = await super().get_updates(
              ^^^^^^^^^^^^^^^^^^^^^^^^^^
  File "C:\Proga\Python_project\Work\venv\Lib\site-packages\telegram\_bot.py", line 4601, in get_updates
    await self._post(
  File "C:\Proga\Python_project\Work\venv\Lib\site-packages\telegram\_bot.py", line 697, in _post
    return await self._do_post(
           ^^^^^^^^^^^^^^^^^^^^
  File "C:\Proga\Python_project\Work\venv\Lib\site-packages\telegram\ext\_extbot.py", line 369, in _do_post
    return await super()._do_post(
           ^^^^^^^^^^^^^^^^^^^^^^^
  File "C:\Proga\Python_project\Work\venv\Lib\site-packages\telegram\_bot.py", line 726, in _do_post
    result = await request.post(
             ^^^^^^^^^^^^^^^^^^^
  File "C:\Proga\Python_project\Work\venv\Lib\site-packages\telegram\request\_baserequest.py", line 197, in post
    result = await self._request_wrapper(
             ^^^^^^^^^^^^^^^^^^^^^^^^^^^^
  File "C:\Proga\Python_project\Work\venv\Lib\site-packages\telegram\request\_baserequest.py", line 355, in _request_wrapper
    raise Conflict(message)
telegram.error.Conflict: Conflict: terminated by other getUpdates request; make sure that only one bot instance is running
2025-06-13 13:10:07 [ERROR] [_application] No error handlers are registered, logging exception.
Traceback (most recent call last):
  File "C:\Proga\Python_project\Work\venv\Lib\site-packages\telegram\ext\_utils\networkloop.py", line 115, in network_retry_loop
    if not await do_action():
           ^^^^^^^^^^^^^^^^^
  File "C:\Proga\Python_project\Work\venv\Lib\site-packages\telegram\ext\_utils\networkloop.py", line 108, in do_action
    return action_cb_task.result()
           ^^^^^^^^^^^^^^^^^^^^^^^
  File "C:\Proga\Python_project\Work\venv\Lib\site-packages\telegram\ext\_updater.py", line 335, in polling_action_cb
    updates = await self.bot.get_updates(
              ^^^^^^^^^^^^^^^^^^^^^^^^^^^
  File "C:\Proga\Python_project\Work\venv\Lib\site-packages\telegram\ext\_extbot.py", line 669, in get_updates
    updates = await super().get_updates(
              ^^^^^^^^^^^^^^^^^^^^^^^^^^
  File "C:\Proga\Python_project\Work\venv\Lib\site-packages\telegram\_bot.py", line 4601, in get_updates
    await self._post(
  File "C:\Proga\Python_project\Work\venv\Lib\site-packages\telegram\_bot.py", line 697, in _post
    return await self._do_post(
           ^^^^^^^^^^^^^^^^^^^^
  File "C:\Proga\Python_project\Work\venv\Lib\site-packages\telegram\ext\_extbot.py", line 369, in _do_post
    return await super()._do_post(
           ^^^^^^^^^^^^^^^^^^^^^^^
  File "C:\Proga\Python_project\Work\venv\Lib\site-packages\telegram\_bot.py", line 726, in _do_post
    result = await request.post(
             ^^^^^^^^^^^^^^^^^^^
  File "C:\Proga\Python_project\Work\venv\Lib\site-packages\telegram\request\_baserequest.py", line 197, in post
    result = await self._request_wrapper(
             ^^^^^^^^^^^^^^^^^^^^^^^^^^^^
  File "C:\Proga\Python_project\Work\venv\Lib\site-packages\telegram\request\_baserequest.py", line 355, in _request_wrapper
    raise Conflict(message)
telegram.error.Conflict: Conflict: terminated by other getUpdates request; make sure that only one bot instance is running
2025-06-13 13:10:28 [ERROR] [_application] No error handlers are registered, logging exception.
Traceback (most recent call last):
  File "C:\Proga\Python_project\Work\venv\Lib\site-packages\telegram\ext\_utils\networkloop.py", line 115, in network_retry_loop
    if not await do_action():
           ^^^^^^^^^^^^^^^^^
  File "C:\Proga\Python_project\Work\venv\Lib\site-packages\telegram\ext\_utils\networkloop.py", line 108, in do_action
    return action_cb_task.result()
           ^^^^^^^^^^^^^^^^^^^^^^^
  File "C:\Proga\Python_project\Work\venv\Lib\site-packages\telegram\ext\_updater.py", line 335, in polling_action_cb
    updates = await self.bot.get_updates(
              ^^^^^^^^^^^^^^^^^^^^^^^^^^^
  File "C:\Proga\Python_project\Work\venv\Lib\site-packages\telegram\ext\_extbot.py", line 669, in get_updates
    updates = await super().get_updates(
              ^^^^^^^^^^^^^^^^^^^^^^^^^^
  File "C:\Proga\Python_project\Work\venv\Lib\site-packages\telegram\_bot.py", line 4601, in get_updates
    await self._post(
  File "C:\Proga\Python_project\Work\venv\Lib\site-packages\telegram\_bot.py", line 697, in _post
    return await self._do_post(
           ^^^^^^^^^^^^^^^^^^^^
  File "C:\Proga\Python_project\Work\venv\Lib\site-packages\telegram\ext\_extbot.py", line 369, in _do_post
    return await super()._do_post(
           ^^^^^^^^^^^^^^^^^^^^^^^
  File "C:\Proga\Python_project\Work\venv\Lib\site-packages\telegram\_bot.py", line 726, in _do_post
    result = await request.post(
             ^^^^^^^^^^^^^^^^^^^
  File "C:\Proga\Python_project\Work\venv\Lib\site-packages\telegram\request\_baserequest.py", line 197, in post
    result = await self._request_wrapper(
             ^^^^^^^^^^^^^^^^^^^^^^^^^^^^
  File "C:\Proga\Python_project\Work\venv\Lib\site-packages\telegram\request\_baserequest.py", line 355, in _request_wrapper
    raise Conflict(message)
telegram.error.Conflict: Conflict: terminated by other getUpdates request; make sure that only one bot instance is running
2025-06-13 13:10:33 [ERROR] [_application] No error handlers are registered, logging exception.
Traceback (most recent call last):
  File "C:\Proga\Python_project\Work\venv\Lib\site-packages\telegram\ext\_utils\networkloop.py", line 115, in network_retry_loop
    if not await do_action():
           ^^^^^^^^^^^^^^^^^
  File "C:\Proga\Python_project\Work\venv\Lib\site-packages\telegram\ext\_utils\networkloop.py", line 108, in do_action
    return action_cb_task.result()
           ^^^^^^^^^^^^^^^^^^^^^^^
  File "C:\Proga\Python_project\Work\venv\Lib\site-packages\telegram\ext\_updater.py", line 335, in polling_action_cb
    updates = await self.bot.get_updates(
              ^^^^^^^^^^^^^^^^^^^^^^^^^^^
  File "C:\Proga\Python_project\Work\venv\Lib\site-packages\telegram\ext\_extbot.py", line 669, in get_updates
    updates = await super().get_updates(
              ^^^^^^^^^^^^^^^^^^^^^^^^^^
  File "C:\Proga\Python_project\Work\venv\Lib\site-packages\telegram\_bot.py", line 4601, in get_updates
    await self._post(
  File "C:\Proga\Python_project\Work\venv\Lib\site-packages\telegram\_bot.py", line 697, in _post
    return await self._do_post(
           ^^^^^^^^^^^^^^^^^^^^
  File "C:\Proga\Python_project\Work\venv\Lib\site-packages\telegram\ext\_extbot.py", line 369, in _do_post
    return await super()._do_post(
           ^^^^^^^^^^^^^^^^^^^^^^^
  File "C:\Proga\Python_project\Work\venv\Lib\site-packages\telegram\_bot.py", line 726, in _do_post
    result = await request.post(
             ^^^^^^^^^^^^^^^^^^^
  File "C:\Proga\Python_project\Work\venv\Lib\site-packages\telegram\request\_baserequest.py", line 197, in post
    result = await self._request_wrapper(
             ^^^^^^^^^^^^^^^^^^^^^^^^^^^^
  File "C:\Proga\Python_project\Work\venv\Lib\site-packages\telegram\request\_baserequest.py", line 355, in _request_wrapper
    raise Conflict(message)
telegram.error.Conflict: Conflict: terminated by other getUpdates request; make sure that only one bot instance is running
2025-06-13 13:10:40 [ERROR] [_application] No error handlers are registered, logging exception.
Traceback (most recent call last):
  File "C:\Proga\Python_project\Work\venv\Lib\site-packages\telegram\ext\_utils\networkloop.py", line 115, in network_retry_loop
    if not await do_action():
           ^^^^^^^^^^^^^^^^^
  File "C:\Proga\Python_project\Work\venv\Lib\site-packages\telegram\ext\_utils\networkloop.py", line 108, in do_action
    return action_cb_task.result()
           ^^^^^^^^^^^^^^^^^^^^^^^
  File "C:\Proga\Python_project\Work\venv\Lib\site-packages\telegram\ext\_updater.py", line 335, in polling_action_cb
    updates = await self.bot.get_updates(
              ^^^^^^^^^^^^^^^^^^^^^^^^^^^
  File "C:\Proga\Python_project\Work\venv\Lib\site-packages\telegram\ext\_extbot.py", line 669, in get_updates
    updates = await super().get_updates(
              ^^^^^^^^^^^^^^^^^^^^^^^^^^
  File "C:\Proga\Python_project\Work\venv\Lib\site-packages\telegram\_bot.py", line 4601, in get_updates
    await self._post(
  File "C:\Proga\Python_project\Work\venv\Lib\site-packages\telegram\_bot.py", line 697, in _post
    return await self._do_post(
           ^^^^^^^^^^^^^^^^^^^^
  File "C:\Proga\Python_project\Work\venv\Lib\site-packages\telegram\ext\_extbot.py", line 369, in _do_post
    return await super()._do_post(
           ^^^^^^^^^^^^^^^^^^^^^^^
  File "C:\Proga\Python_project\Work\venv\Lib\site-packages\telegram\_bot.py", line 726, in _do_post
    result = await request.post(
             ^^^^^^^^^^^^^^^^^^^
  File "C:\Proga\Python_project\Work\venv\Lib\site-packages\telegram\request\_baserequest.py", line 197, in post
    result = await self._request_wrapper(
             ^^^^^^^^^^^^^^^^^^^^^^^^^^^^
  File "C:\Proga\Python_project\Work\venv\Lib\site-packages\telegram\request\_baserequest.py", line 355, in _request_wrapper
    raise Conflict(message)
telegram.error.Conflict: Conflict: terminated by other getUpdates request; make sure that only one bot instance is running
2025-06-13 13:10:46 [ERROR] [_application] No error handlers are registered, logging exception.
Traceback (most recent call last):
  File "C:\Proga\Python_project\Work\venv\Lib\site-packages\telegram\ext\_utils\networkloop.py", line 115, in network_retry_loop
    if not await do_action():
           ^^^^^^^^^^^^^^^^^
  File "C:\Proga\Python_project\Work\venv\Lib\site-packages\telegram\ext\_utils\networkloop.py", line 108, in do_action
    return action_cb_task.result()
           ^^^^^^^^^^^^^^^^^^^^^^^
  File "C:\Proga\Python_project\Work\venv\Lib\site-packages\telegram\ext\_updater.py", line 335, in polling_action_cb
    updates = await self.bot.get_updates(
              ^^^^^^^^^^^^^^^^^^^^^^^^^^^
  File "C:\Proga\Python_project\Work\venv\Lib\site-packages\telegram\ext\_extbot.py", line 669, in get_updates
    updates = await super().get_updates(
              ^^^^^^^^^^^^^^^^^^^^^^^^^^
  File "C:\Proga\Python_project\Work\venv\Lib\site-packages\telegram\_bot.py", line 4601, in get_updates
    await self._post(
  File "C:\Proga\Python_project\Work\venv\Lib\site-packages\telegram\_bot.py", line 697, in _post
    return await self._do_post(
           ^^^^^^^^^^^^^^^^^^^^
  File "C:\Proga\Python_project\Work\venv\Lib\site-packages\telegram\ext\_extbot.py", line 369, in _do_post
    return await super()._do_post(
           ^^^^^^^^^^^^^^^^^^^^^^^
  File "C:\Proga\Python_project\Work\venv\Lib\site-packages\telegram\_bot.py", line 726, in _do_post
    result = await request.post(
             ^^^^^^^^^^^^^^^^^^^
  File "C:\Proga\Python_project\Work\venv\Lib\site-packages\telegram\request\_baserequest.py", line 197, in post
    result = await self._request_wrapper(
             ^^^^^^^^^^^^^^^^^^^^^^^^^^^^
  File "C:\Proga\Python_project\Work\venv\Lib\site-packages\telegram\request\_baserequest.py", line 355, in _request_wrapper
    raise Conflict(message)
telegram.error.Conflict: Conflict: terminated by other getUpdates request; make sure that only one bot instance is running
2025-06-13 13:11:44 [ERROR] [logger] Торговой пары SOL-USDT-250704 не существует
2025-06-13 13:11:44 [ERROR] [main] Analysis error: Ошибка валидации данных от Bybit. Проверьте вводимые данные. Для подробностей обратитесь к админу
2025-06-13 13:13:08 [ERROR] [logger] Торговой пары ETH-USDT-250704 не существует
2025-06-13 13:13:08 [ERROR] [main] Analysis error: Ошибка валидации данных от Bybit. Проверьте вводимые данные. Для подробностей обратитесь к админу
2025-06-13 13:24:18 [ERROR] [networkloop] Network Retry Loop (Bootstrap Initialize Application): Invalid token. Aborting retry loop.
Traceback (most recent call last):
  File "C:\Proga\Python_project\Work\venv\Lib\site-packages\telegram\_bot.py", line 844, in initialize
    await self.get_me()
  File "C:\Proga\Python_project\Work\venv\Lib\site-packages\telegram\ext\_extbot.py", line 1980, in get_me
    return await super().get_me(
           ^^^^^^^^^^^^^^^^^^^^^
  File "C:\Proga\Python_project\Work\venv\Lib\site-packages\telegram\_bot.py", line 975, in get_me
    result = await self._post(
             ^^^^^^^^^^^^^^^^^
  File "C:\Proga\Python_project\Work\venv\Lib\site-packages\telegram\_bot.py", line 697, in _post
    return await self._do_post(
           ^^^^^^^^^^^^^^^^^^^^
  File "C:\Proga\Python_project\Work\venv\Lib\site-packages\telegram\ext\_extbot.py", line 369, in _do_post
    return await super()._do_post(
           ^^^^^^^^^^^^^^^^^^^^^^^
  File "C:\Proga\Python_project\Work\venv\Lib\site-packages\telegram\_bot.py", line 726, in _do_post
    result = await request.post(
             ^^^^^^^^^^^^^^^^^^^
  File "C:\Proga\Python_project\Work\venv\Lib\site-packages\telegram\request\_baserequest.py", line 197, in post
    result = await self._request_wrapper(
             ^^^^^^^^^^^^^^^^^^^^^^^^^^^^
  File "C:\Proga\Python_project\Work\venv\Lib\site-packages\telegram\request\_baserequest.py", line 351, in _request_wrapper
    raise InvalidToken(message)
telegram.error.InvalidToken: Not Found

The above exception was the direct cause of the following exception:

Traceback (most recent call last):
  File "C:\Proga\Python_project\Work\venv\Lib\site-packages\telegram\ext\_utils\networkloop.py", line 115, in network_retry_loop
    if not await do_action():
           ^^^^^^^^^^^^^^^^^
  File "C:\Proga\Python_project\Work\venv\Lib\site-packages\telegram\ext\_utils\networkloop.py", line 93, in do_action
    return await action_cb()
           ^^^^^^^^^^^^^^^^^
  File "C:\Proga\Python_project\Work\venv\Lib\site-packages\telegram\ext\_application.py", line 486, in initialize
    await self.bot.initialize()
  File "C:\Proga\Python_project\Work\venv\Lib\site-packages\telegram\ext\_extbot.py", line 315, in initialize
    await super().initialize()
  File "C:\Proga\Python_project\Work\venv\Lib\site-packages\telegram\_bot.py", line 846, in initialize
    raise InvalidToken(f"The token `{self._token}` was rejected by the server.") from exc
telegram.error.InvalidToken: The token `YOUR_BOT_TOKEN_HERE` was rejected by the server.
